<?xml version="1.0" ?>
<robot name="arm">
  <material name="default"/>

  <link name="base" >
    <inertial>
      <origin rpy = "0 0 0" xyz = "0 0 0" />
      <mass value = "0.0001" />
      <inertia ixx = "0.0001" ixy = "0" ixz = "0" iyy = "0.0001" iyz = "0" izz = "0.0001" />
    </inertial>
  </link>

  <link name="root" >
    <inertial>
      <origin rpy = "0 0 0" xyz = "0.00 0.00 0.00" />
      <mass value = "100.000000" />
      <inertia ixx = "1.25" ixy = "0" ixz = "0" iyy = "1.25" iyz = "0" izz = "0.01" />
    </inertial>
    <collision>
      <origin rpy = "0 0 0" xyz = "0.00 0.00 0.00" />
      <geometry>
        <box size="0.50 0.50 0.10"/>
      </geometry>
      <material name="">
        <contact name="default"/>
      </material>
    </collision>
    <!-- <visual>
      <origin rpy = "0 0 0" xyz = "0.00 0.00 0.00" />
      <geometry>
        <box size="0.50 0.50 0.10"/>
      </geometry>
    </visual> -->
  </link>

  <joint name="root" type="fixed" >
    <parent link = "base" />
    <child link="root" />
    <origin rpy = "0 0 0" xyz = "0.000000 0.000000 0.000000" />
  </joint>

  <link name="shoulder" >
    <inertial>
      <origin rpy = "0 0 0" xyz = "0.000000 0.000000 -0.140000" />
      <mass value = "1.500000" />
      <inertia ixx = "0.008087" ixy = "0" ixz = "0" iyy = "0.008087" iyz = "0" izz = "0.001443" />
    </inertial>
    <collision>
      <origin rpy = "0 0 0" xyz = "0.000000 0.000000 -0.140000" />
      <geometry>
        <capsule length="0.180000" radius="0.045000"/>
      </geometry>
    </collision>
    <visual>
      <origin rpy = "0 0 0" xyz = "0.000000 0.000000 -0.140000" />
      <geometry>
        <capsule length="0.180000" radius="0.045000"/>
      </geometry>
    </visual>
  </link>  

  <joint name="shoulder" type="spherical" >
    <parent link="root" />
    <child link="shoulder" />
    <origin rpy = "0 0 0" xyz = "1.0 0.0 1.0" />
    <!-- <origin rpy = "0 0 0" xyz = "0.0 0.0 1.0" /> -->
  </joint>

  <link name="elbow" >
    <inertial>
      <origin rpy = "0 0 0" xyz = "0.000000 0.000000 -0.120000" />
      <mass value = "1.000000" />
      <inertia ixx = "0.003420" ixy = "0" ixz = "0" iyy = "0.003420" iyz = "0" izz = "0.000755" />
    </inertial>
    <collision>
      <origin rpy = "0 0 0" xyz = "0.000000 0.000000 -0.120000" />
      <geometry>
        <capsule length="0.135" radius="0.04"/>
      </geometry>
    </collision>
    <visual>
      <origin rpy = "0 0 0" xyz = "0.000000 0.000000 -0.120000" />
      <geometry>
        <capsule length="0.135" radius="0.04"/>
      </geometry>
    </visual>
  </link>

  <joint name="elbow" type="revolute" >
    <parent link="shoulder" />
    <child link="elbow" />
    <limit effort="1000.0" lower="0" upper="3.14" velocity="100.5"/>
    <origin rpy = "0 0 0" xyz = "0.000000 0.000000 -0.274788" />
    <axis xyz = "0.000000 -1.000000 0.000000" />
  </joint>

  <link name="wrist" >
    <inertial>
      <origin rpy = "0 0 0" xyz = "0.000000 0.000000 -0.052500" />
      <mass value = "1.000000" />
      <inertia ixx = "0.000927" ixy = "0" ixz = "0" iyy = "0.002863" iyz = "0" izz = "0.003286" />
    </inertial>
    <collision>
      <origin rpy = "0 0 0" xyz = "0.000000 0.000000 -0.052500" />
      <geometry>
        <box size="0.177000 0.090000 0.03000" />
      </geometry>
      <material name="">
        <contact name="default"/>
      </material>
    </collision>
    <visual>
      <origin rpy = "0 0 0" xyz = "0.000000 0.000000 -0.052500" />
      <geometry>
        <box size="0.03000 0.090000 0.177000" />
      </geometry>
    </visual>
  </link>

  <joint name="wrist" type="spherical" >
    <parent link="elbow" />
    <child link="wrist" />
    <origin rpy = "0 0 0" xyz = "0.000000 0.000000 -0.258947" />
  </joint>

  <link name="forward">
    <inertial>
      <original rpy = "0 0 0" xyz = "0.0 0.0 0.0" />
      <mass value = "0.00001"/>
      <intertia ixx = "0.00001" ixy = "0" ixz = "0" iyy = "0.00001" iyz = "0" izz = "0.00001"/>
    </inertial>
    <collision>
      <original rpy = "0 0 0" xyz = "0.0 0.0 0.0" />
      <geometry>
        <capsule length="0.075000" radius="0.015"/>
      </geometry>
      <material name="">
        <contact name="default"/>
      </material>
    </collision>
    <visual>
      <original rpy = "0 0 0" xyz = "0.0 0.0 0.0" />
      <geometry>
        <capsule length="0.075000" radius="0.015"/>
      </geometry>
    </visual>
  </link>

  <joint name="forward" type="fixed">
    <parent link="wrist"/>
    <child link="forward"/>
    <origin rpy = "1.5708 0 0" xyz = "0.0 0.0 -0.139"/>
  </joint>

  <link name="backward">
    <inertial>
      <original rpy = "0 0 0" xyz = "0.0 0.0 0.0" />
      <mass value = "0.00001"/>
      <intertia ixx = "0.00001" ixy = "0" ixz = "0" iyy = "0.00001" iyz = "0" izz = "0.00001"/>
    </inertial>
    <collision>
      <original rpy = "0 0 0" xyz = "0.0 0.0 0.0" />
      <geometry>
        <capsule length="0.075000" radius="0.015"/>
      </geometry>
      <material name="">
        <contact name="default"/>
      </material>
    </collision>
    <visual>
      <original rpy = "0 0 0" xyz = "0.0 0.0 0.0" />
      <geometry>
        <capsule length="0.075000" radius="0.015"/>
      </geometry>
    </visual>
  </link>

  <joint name="backward" type="fixed">
    <parent link="wrist"/>
    <child link="backward"/>
    <origin rpy = "1.5708 0 0" xyz = "0.0 0.0 0.0387"/>
  </joint>

  <link name="right">
    <inertial>
      <original rpy = "0 0 0" xyz = "0.0 0.0 0.0" />
      <mass value = "0.00001"/>
      <intertia ixx = "0.00001" ixy = "0" ixz = "0" iyy = "0.00001" iyz = "0" izz = "0.00001"/>
    </inertial>
    <collision>
      <original rpy = "0 0 0" xyz = "0.0 0.0 0.0" />
      <geometry>
        <capsule length="0.177000" radius="0.015"/>
      </geometry>
      <material name="">
        <contact name="default"/>
      </material>
    </collision>
    <visual>
      <original rpy = "0 0 0" xyz = "0.0 0.0 0.0" />
      <geometry>
        <capsule length="0.177000" radius="0.015"/>
      </geometry>
    </visual>
  </link>

  <joint name="right" type="fixed">
    <parent link="wrist"/>
    <child link="right"/>
    <origin rpy = "0 0 0" xyz = "0.0 -0.045 -0.05"/>
  </joint>

  <link name="left">
    <inertial>
      <original rpy = "0 0 0" xyz = "0.0 0.0 0.0" />
      <mass value = "0.00001"/>
      <intertia ixx = "0.00001" ixy = "0" ixz = "0" iyy = "0.00001" iyz = "0" izz = "0.00001"/>
    </inertial>
    <collision>
      <original rpy = "0 0 0" xyz = "0.0 0.0 0.0" />
      <geometry>
        <capsule length="0.177000" radius="0.015"/>
      </geometry>
      <material name="">
        <contact name="default"/>
      </material>
    </collision>
    <visual>
      <original rpy = "0 0 0" xyz = "0.0 0.0 0.0" />
      <geometry>
        <capsule length="0.177000" radius="0.015"/>
      </geometry>
    </visual>
  </link>

  <joint name="left" type="fixed">
    <parent link="wrist"/>
    <child link="left"/>
    <origin rpy = "0 0 0" xyz = "0.0 0.045 -0.05"/>
  </joint>

</robot>
